Workbook

Sheet 表紙
B4: 晴れる屋様
B5: サイトリニューアル
B6: 基本設計仕様書
B7: 分析・集計管理機能
B10: Ver | C10: 改訂内容 | D10: 改訂者 | E10: 改訂日
B11: 0.1 | C11: 新規作成 | D11: 高久 | E11: 45847
B12: 0.2 | C12: レビュー指摘箇所の修正 | D12: 高久 | E12: 45903

Sheet 目次
B1: 目次
C3: 画面遷移設計
C4: 画面遷移図
C6: 画面設計
C7: M12-01 日別・月別集計 集計一覧(検索項目-日別)
C8: M12-01 日別・月別集計 集計一覧(検索項目-月別)
C9: M12-01 日別・月別集計 集計一覧表示(検索結果-日別)
C10: M12-01 日別・月別集計 集計一覧表示(検索結果-月別)
C11: M12-02 日別・月別集計 CSV出力
C12: M12-03 受注売上分析 集計一覧(検索項目)
C13: M12-03 受注売上分析 集計一覧(検索結果 / 集計単位:商品 )
C14: M12-03 受注売上分析 集計一覧(検索結果 / 集計単位:カテゴリ)
C15: M12-04 受注売上分析 CSV出力(集計単位:商品)
... C24: M12-10 特集タグ編集CSVダウンロード CSV出力

Sheet 画面遷移図
A1: ドキュメント名 | I1: =表紙!$B$7 -> 分析・集計管理機能 | U1: セクション
A2: プロジェクト名 | I2: =表紙!$B$5 -> サイトリニューアル | U2: 作成者 | Y2: 45847 | AC2: 作成日 | AG2: 高久 | AK2: 更新者 | AS2: 更新日
B4: 説明
B5: ・分析・集計機能の画面遷移図
B8: 画面遷移図（管理画面）

Sheet 日別・月別集計 集計一覧(検索項目-日別) 
A1: ドキュメント名 | I1: =表紙!$B$7 -> 分析・集計管理機能 | U1: セクション
A2: プロジェクト名 | I2: =表紙!$B$5 -> サイトリニューアル | U2: 作成者 | Y2: 高久 | AC2: 作成日 | AG2: 45847 | AK2: 更新者 | AS2: 更新日
A4: 機能No | D4: M12-01 | I4: 機能名 | N4: 日別・月別集計 集計一覧表示 | AC4: 概要 | AG4: 受注データを使って日別・月別の集計を行うことが可能
B6: レイアウト図
B50: カスタマイズ説明
B51: ・カスタマイズ要件
C52: ・ | D52: 集計方式の変更
C53: ・ | D53: 検索項目について
C54: ・ | D54: スマレジについて
C56: カスタマイズ要件に記載の内容以外は現行踏襲とする
B59: 処理概要（★はカスタマイズ項目）
B60: 概要
C61: 受注データを使って日別・月別の集計を行うことが可能
B63: 機能
C64: 現行機能をベースに下記のカスタマイズを行う
C66: 集計方式の変更
D67: ・ | E67: 集計は売上として計上できるものとし、それ以外の対応状況は計上しない
E68: (注文ステータスが「出荷完了」のみ集計対象とする)
D69: ・ | E69: 集計データをバッチであらかじめ作成することで速度改善を行う
C71: 検索項目について
D72: ・ | E72: 検索項目は以下の項目に固定とする
E73: ・ | F73: 識別ID 1 : 集計タイプ(既存)
E74: ・ | F74: 識別ID 2～3 :集計日(既存)
E75: ・ | F75: 識別ID 4～6:集計対象(新規)
D76: ・ | E76: 売上集計用に検索項目に出力するフラグを店舗管理に持たせる(追加)
D77: ・ | E77: 今回のカスタマイズに伴い、下記項目は削除する
E78: ・ | F78: 利用端末
E79: ・ | F79: 表示項目(注文) ※検索結果の出力項目が固定になるため
E80: ・ | F80: 表示項目(詳細) ※検索結果の出力項目が固定になるため
D81: ・ | E81: 識別ID 1:集計タイプの切り替えを行うたびに、集計日の値が上書きされる
E82: ・ | F82: 集計タイプが「日別」の場合、集計日は「当月1日」から「当月末日」を自動入力
E83: ・ | F83: 集計タイプが「月別」の場合、集計月は「2か月前」から「当月」を自動入力
D84: ・ | E84: 識別ID 4:集計対象(通販)にチェックを入れた場合、通販の売上集計を行う
D85: ・ | E85: 識別ID 5:集計対象(各店舗)の追加。店舗一覧から売上集計したい店舗にチェックを入れる
E86: 初期設定として、店舗一覧にログインしたユーザーが所属している店舗にチェックが入った状態で表示される(追加)
D87: ・ | E87: 識別ID 6:店舗全選択/全解除のチェックボックスは、識別ID 5:集計対象(各店舗)の全チェックボックスと連動
E88: チェックを入れると、識別ID 5:集計対象(各店舗)にある全店舗のチェックボックスにチェックが入る
E89: チェックを外すと、識別ID 5:集計対象(各店舗)にある全店舗のチェックボックスにチェックが外れる
C91: スマレジについて
D92: ・ | E92: スマレジの取引データは基本的にリアルタイムに送信される
...

Sheet 日別・月別集計 集計一覧(検索項目-月別)
A1: ドキュメント名 | I1: =表紙!$B$7 -> 分析・集計管理機能 | U1: セクション
A2: プロジェクト名 | I2: =表紙!$B$5 -> サイトリニューアル | U2: 作成者 | Y2: 高久 | AC2: 作成日 | AG2: 45847 | AK2: 更新者 | AS2: 更新日
A4: 機能No | D4: M12-01 | I4: 機能名 | N4: 日別・月別集計 集計一覧表示 | AC4: 概要 | AG4: 受注データを使って日別・月別の集計を行うことが可能
B6: レイアウト図
B48: カスタマイズ説明
B49: ・カスタマイズ要件
C50: ・ | D50: 集計方式の変更
C51: ・ | D51: 検索項目について
C52: ・ | D52: スマレジについて
C54: カスタマイズ要件に記載の内容以外は現行踏襲とする
B57: 処理概要（★はカスタマイズ項目）
B58: 概要
C59: 受注データを使って日別・月別の集計を行うことが可能
B61: 機能
C62: 現行機能をベースに下記のカスタマイズを行う
C64: 集計方式の変更
D65: ・ | E65: 集計は売上として計上できるものとし、それ以外の対応状況は計上しない
E66: (注文ステータスが「出荷完了」のみ集計対象とする)
D67: ・ | E67: 集計データをバッチであらかじめ作成することで速度改善を行う
C69: 検索項目について
D70: ・ | E70: 検索項目は以下の項目に固定とする
E71: ・ | F71: 識別ID 1 : 集計タイプ(既存)
E72: ・ | F72: 識別ID 2～3 :集計日(既存)
E73: ・ | F73: 識別ID 4～5:集計対象(新規)
D74: ・ | E74: 売上集計用に検索項目に出力するフラグを店舗管理に持たせる(追加)
D75: ・ | E75: 今回のカスタマイズに伴い、下記項目は削除する
E76: ・ | F76: 利用端末
E77: ・ | F77: 表示項目(注文) ※検索結果の出力項目が固定になるため
E78: ・ | F78: 表示項目(詳細) ※検索結果の出力項目が固定になるため
D79: ・ | E79: 売上集計用に検索項目に出力するフラグを店舗管理に持たせる
D80: ・ | E80: 識別ID 1:集計タイプの切り替えを行うたびに、集計日の値が上書きされる
E81: ・ | F81: 集計タイプが「日別」の場合、集計日は「当月1日」から「当月末日」を自動入力
E82: ・ | F82: 集計タイプが「月別」の場合、集計月は「2か月前」から「当月」を自動入力
D83: ・ | E83: 識別ID 4:集計対象(通販)にチェックを入れた場合、通販の売上集計を行う
D84: ・ | E84: 識別ID 5:集計対象(各店舗)の追加。店舗一覧から売上集計したい店舗にチェックを入れる
E85: 初期設定として、店舗一覧にログインしたユーザーが所属している店舗にチェックが入った状態で表示される(追加)
D86: ・ | E86: 識別ID 6:店舗全選択/全解除のチェックボックスは、識別ID 5:集計対象(各店舗)の全チェックボックスと連動
E87: チェックを入れると、識別ID 5:集計対象(各店舗)にある全店舗のチェックボックスにチェックが入る
E88: チェックを外すと、識別ID 5:集計対象(各店舗)にある全店舗のチェックボックスにチェックが外れる
C90: スマレジについて
...

Sheet 日別・月別集計 集計一覧(検索結果-日別)
A1: ドキュメント名 | I1: =表紙!$B$7 -> 分析・集計管理機能 | U1: セクション
A2: プロジェクト名 | I2: =表紙!$B$5 -> サイトリニューアル | U2: 作成者 | Y2: 高久 | AC2: 作成日 | AG2: 45847 | AK2: 更新者 | AO2: 堀部 | AS2: 更新日 | AW2: 45958
A4: 機能No | D4: M12-01 | I4: 機能名 | N4: 日別・月別集計 集計一覧表示 | AC4: 概要 | AG4: 受注データを使って日別・月別の集計を行うことが可能
B6: レイアウト図
B38: カスタマイズ説明
B39: ・カスタマイズ要件
C40: ・ | D40: 集計方式の変更
C41: ・ | D41: 集計項目の固定
C42: ・ | D42: スマレジについて
C44: カスタマイズ要件に記載の内容以外は現行踏襲とする
B47: 処理概要（★はカスタマイズ項目）
C49: 概要
D50: 受注データを使って日別・月別の集計を行うことが可能
B52: ★ | C52: 集計方式の変更
D53: ・ | E53: 販売関連の集計は注文データの注文ステータスが「出荷完了」のみ計上し、それ以外の注文ステータスは計上しない
D54: ・ | E54: 買取関連の集計は買取データの買取ステータスが「買取成立」のみ計上し、それ以外の買取ステータスは計上しない
B56: ★ | C56: 集計項目の固定
D57: 今回のカスタマイズで、結果出力時の項目を固定とする
D58: ・ | E58: 識別ID 2: 「支店名」を追加。「通販」もしくは指定された「店舗名」または「その他」を出力
F59: ※「その他」は通販・各店舗に該当しない売上を計上
D60: ・ | E60: 識別ID 3: 「総売上」を追加。通販・店舗毎の売上総件数を出力
D61: ・ | E61: 識別ID 4: 「原価」を追加。通販・店舗毎の原価合計を出力
D62: ・ | E62: 識別ID 5: 「粗利益高」を追加。通販・店舗毎の粗利益高を出力
F63: 計算式 : 粗利益高=総売上 - 原価
D64: ・ | E64: 識別ID 6 : 「販売点数」を追加。通販・店舗毎の販売点数を出力
D65: ・ | E65: 識別ID 7: 「取引数」を追加。通販・店舗毎の取引数を出力
D66: ・ | E66: 識別ID 8: 「取引単価(平均)」を追加。通販・店舗毎に1回の取引に対しての購入金額平均を出力
D67: ・ | E67: 識別ID 9: 「買取件数」を追加。通販・店舗毎に買取が行われた取引件数
D68: ・ | E68: 識別ID 10: 「買取金額」を追加。通販・店舗毎の買取合計を出力
D69: ・ | E69: 識別ID 11: 「廃棄」を追加。在庫変動区分が「廃棄」となっているものを集計し廃棄コスト合計を出力
E70: ※在庫変動区分の子区分が廃棄(イベント商品)、廃棄(他事業移動)となっているものは廃棄の集計に含めない
D71: ・ | E71: 識別ID 12: 「欠品」を追加。在庫変動区分が「欠品」となっているものを集計しコスト合計を出力
D72: ・ | E72: 識別ID 14: 「総合計」を追加。識別ID3～12各列のそれぞれの総合計を出力
B74: ★ | C74: スマレジについて
D75: ・ | E75: スマレジの取引データは基本的にリアルタイムに送信される
D76: ・ | E76: 本店のほか、支店やスマレジの取引情報も集計対象として取り扱う
B79: 識別ID | E79: ラベル | M79: 書式・制限 | T79: 必須 | V79: 最大文字数 または最大値 | Z79: 初期値 | AG79: 画面部品の説明
B80: 1 | E80: 集計日 | M80: テキスト(日付) | T80: - | V80: - | Z80: -
B81: 2 | E81: 店舗名 | M81: テキスト | T81: - | V81: - | Z81: - | AG81: ※カスタマイズ対応、新規項目
B82: 3 | E82: 総売上 | M82: 数値(整数) | T82: - | V82: - | Z82: - | AG82: ※カスタマイズ対応、新規項目
...

Sheet 日別・月別集計 集計一覧(検索結果-月別)
A1: ドキュメント名 | I1: =表紙!$B$7 -> 分析・集計管理機能 | U1: セクション
A2: プロジェクト名 | I2: =表紙!$B$5 -> サイトリニューアル | U2: 作成者 | Y2: 高久 | AC2: 作成日 | AG2: 45847 | AK2: 更新者 | AO2: 堀部 | AS2: 更新日 | AW2: 45958
A4: 機能No | D4: M12-01 | I4: 機能名 | N4: 日別・月別集計 集計一覧表示 | AC4: 概要 | AG4: 受注データを使って日別・月別の集計を行うことが可能
B6: レイアウト図
B38: カスタマイズ説明
B39: ・カスタマイズ要件
C40: ・ | D40: 集計方式の変更
C41: ・ | D41: 集計項目の固定
C42: ・ | D42: スマレジについて
C44: カスタマイズ要件に記載の内容以外は現行踏襲とする
B47: 処理概要（★はカスタマイズ項目）
C49: 概要
D50: 受注データを使って日別・月別の集計を行うことが可能
B52: ★ | C52: 集計方式の変更
D53: ・ | E53: 販売関連の集計は注文データの注文ステータスが「出荷完了」のみ計上し、それ以外の注文ステータスは計上しない
D54: ・ | E54: 買取関連の集計は買取データの買取ステータスが「買取成立」のみ計上し、それ以外の買取ステータスは計上しない
B56: ★ | C56: 集計項目の固定
D57: 今回のカスタマイズで、結果出力時の項目を固定とする
D58: ・ | E58: 識別ID 2: 「支店名」を追加。「通販」もしくは指定された「店舗名」または「その他」を出力
F59: ※「その他」は通販・各店舗に該当しない売上を計上
D60: ・ | E60: 識別ID 3: 「総売上」を追加。通販・店舗毎の売上総件数を出力
D61: ・ | E61: 識別ID 4: 「原価」を追加。通販・店舗毎の原価合計を出力
D62: ・ | E62: 識別ID 5: 「粗利益高」を追加。通販・店舗毎の粗利益高を出力
F63: 計算式 : 粗利益高=総売上 - 原価
D64: ・ | E64: 識別ID 6 : 「販売点数」を追加。通販・店舗毎の販売点数を出力
D65: ・ | E65: 識別ID 7: 「取引数」を追加。通販・店舗毎の取引数を出力
D66: ・ | E66: 識別ID 8: 「取引単価(平均)」を追加。通販・店舗毎に1回の取引に対しての購入金額平均を出力
D67: ・ | E67: 識別ID 9: 「買取件数」を追加。通販・店舗毎に買取が行われた取引件数
D68: ・ | E68: 識別ID 10: 「買取金額」を追加。通販・店舗毎の買取合計を出力
D69: ・ | E69: 識別ID 11: 「廃棄」を追加。在庫変動区分が「廃棄」となっているものを集計し廃棄コスト合計を出力
D70: ・ | E70: 識別ID 12: 「欠品」を追加。在庫変動区分が「欠品」となっているものを集計しコスト合計を出力
D71: ・ | E71: 識別ID 14: 「総合計」を追加。識別ID3～12各列のそれぞれの総合計を出力
B73: ★ | C73: スマレジについて
D74: ・ | E74: スマレジの取引データは基本的にリアルタイムに送信される
D75: ・ | E75: 本店のほか、支店やスマレジの取引情報も集計対象として取り扱う
B78: 識別ID | E78: ラベル | M78: 書式・制限 | T78: 必須 | V78: 最大文字数 または最大値 | Z78: 初期値 | AG78: 画面部品の説明
B79: 1 | E79: 集計月 | M79: テキスト(年月) | T79: - | V79: - | Z79: -
B80: 2 | E80: 店舗名 | M80: テキスト | T80: - | V80: - | Z80: - | AG80: ※カスタマイズ対応、新規項目
B81: 3 | E81: 総売上 | M81: 数値(整数) | T81: - | V81: - | Z81: - | AG81: ※カスタマイズ対応、新規項目
B82: 4 | E82: 原価 | M82: 数値(整数) | T82: - | V82: - | Z82: - | AG82: ※カスタマイズ対応、新規項目
...

Sheet 日別・月別集計 CSV出力
A1: ドキュメント名 | I1: =表紙!$B$7 -> 分析・集計管理機能 | U1: セクション
A2: プロジェクト名 | I2: =表紙!$B$5 -> サイトリニューアル | U2: 作成者 | Y2: 高久 | AC2: 作成日 | AG2: 45847 | AK2: 更新者 | AO2: 堀部 | AS2: 更新日 | AW2: 45958
A4: 機能No | D4: M12-02 | I4: 機能名 | N4: 日別・月別集計 CSV出力 | AC4: 概要 | AG4: 受注データを使って日別・月別の集計のCSVダウンロードを行うことが可能
B6: M12-02 日別・月別集計 CSV出力
B7: 識別ID | E7: 項目名 | M7: 備考
B8: 1 | E8: 集計日 または 集計月 | M8: ※集計タイプ(日別・月別)によってヘッダー項目名が差し替わる
B9: 2 | E9: 店舗名 | M9: ※カスタマイズ対応、カラム情報は固定
B10: 3 | E10: 総売上 | M10: ※カスタマイズ対応、カラム情報は固定
B11: 4 | E11: 原価 | M11: ※カスタマイズ対応、カラム情報は固定
B12: 5 | E12: 粗利益高 | M12: ※カスタマイズ対応、カラム情報は固定
B13: 6 | E13: 販売点数 | M13: ※カスタマイズ対応、カラム情報は固定
B14: 7 | E14: 取引数 | M14: ※カスタマイズ対応、カラム情報は固定
B15: 8 | E15: 取引単価(平均) | M15: ※カスタマイズ対応、カラム情報は固定
B16: 9 | E16: 買取件数 | M16: ※カスタマイズ対応、カラム情報は固定
B17: 10 | E17: 買取金額 | M17: ※カスタマイズ対応、カラム情報は固定
B18: 11 | E18: 廃棄 | M18: ※カスタマイズ対応、カラム情報は固定
B19: 12 | E19: 欠品 | M19: ※カスタマイズ対応、カラム情報は固定
B21: カスタマイズ説明
B22: ・カスタマイズ要件
C23: ・ | D23: 集計項目の固定
C24: ・ | D24: スマレジについて
C26: カスタマイズ要件に記載の内容以外は現行踏襲とする
B29: 処理概要（★はカスタマイズ項目）
C30: 概要
D31: 受注データを使って日別・月別の集計のCSVダウンロードを行うことが可能
B33: ★ | C33: 集計項目の固定
D34: 今回のカスタマイズで、結果出力時の項目を固定とする
D35: ・ | E35: 識別ID 2: 「支店名」を追加。「通販」もしくは指定された「店舗名」または「その他」を出力
F36: ※「その他」は通販・各店舗に該当しない売上を計上
D37: ・ | E37: 識別ID 3: 「総売上」を追加。通販・店舗毎の売上総件数を出力
D38: ・ | E38: 識別ID 4: 「原価」を追加。通販・店舗毎の原価合計を出力
D39: ・ | E39: 識別ID 5: 「粗利益高」を追加。通販・店舗毎の粗利益高を出力
F40: 計算式 : 粗利益高=総売上 - 原価
D41: ・ | E41: 識別ID 6 : 「販売点数」を追加。通販・店舗毎の販売点数を出力
D42: ・ | E42: 識別ID 7: 「取引数」を追加。通販・店舗毎の取引数を出力
D43: ・ | E43: 識別ID 8: 「取引単価(平均)」を追加。通販・店舗毎に1回の取引に対しての購入金額平均を出力
D44: ・ | E44: 識別ID 9: 「買取件数」を追加。通販・店舗毎に買取が行われた取引件数
D45: ・ | E45: 識別ID 10: 「買取金額」を追加。通販・店舗毎の買取合計を出力
D46: ・ | E46: 識別ID 11: 「廃棄」を追加。在庫変動区分が「廃棄」となっているものを集計し廃棄コスト合計を出力
D47: ・ | E47: 識別ID 12: 「欠品」を追加。在庫変動区分が「欠品」となっているものを集計しコスト合計を出力
...

Sheet 受注売上分析 集計一覧(検索項目)
A1: ドキュメント名 | I1: =表紙!$B$7 -> 分析・集計管理機能 | U1: セクション
A2: プロジェクト名 | I2: =表紙!$B$5 -> サイトリニューアル | U2: 作成者 | Y2: 高久 | AC2: 作成日 | AG2: 45847 | AK2: 更新者 | AO2: 堀部 | AS2: 更新日 | AW2: 45958
A4: 機能No | D4: M12-03 | I4: 機能名 | N4: 受注/売上分析 集計一覧(検索項目) | AC4: 概要 | AG4: 受注データを使って集計単位を指定して集計を行うことが可能
B6: レイアウト図
B59: カスタマイズ説明
B60: ・カスタマイズ要件
C61: ・ | D61: 検索項目について
C62: ・ | D62: スマレジについて
C63: ・ | D63: 集計単位の選択肢を商品・カテゴリのみとし、支払方法、購入グループ、都道府県、性別、利用端末、年代(会員)は削除する
C65: カスタマイズ要件に記載の内容以外は現行踏襲とする
B68: 処理概要（★はカスタマイズ項目）
B69: 概要
C70: 受注データを使って集計単位を指定して集計を行うことが可能
B72: 機能
C73: 現行機能をベースに下記のカスタマイズを行う
B75: 検索項目について
C76: ・ | D76: 下記の項目を削除
D77: ・ | E77: 生年月日
D78: ・ | E78: 性別
D79: ・ | E79: 都道府県
D80: ・ | E80: 利用端末
C82: ・ | D82: 識別ID 3:集計対象(通販)にチェックを入れた場合、通販の売上集計を行う
C83: ・ | D83: 識別ID 4:集計対象(各店舗)の追加。店舗一覧から売上集計したい店舗にチェックを入れる
D84: 初期設定として、店舗一覧にログインしたユーザーが所属している店舗にチェックが入った状態で表示される(追加)
C85: ・ | D85: 識別ID 5:店舗全選択/全解除のチェックボックスは、識別ID 5:集計対象(各店舗)の全チェックボックスと連動
D86: チェックを入れると、識別ID 5:集計対象(各店舗)にある全店舗のチェックボックスにチェックが入る
D87: チェックを外すと、識別ID 5:集計対象(各店舗)にある全店舗のチェックボックスにチェックが外れる
C89: ・ | D89: 識別ID 7:集計日(To)について、デフォルトの値を当月末日に設定
D90: 例 | E90: 2025-7-31 23:59:59
C92: ・ | D92: 識別ID:8 集計単位の選択肢を商品・カテゴリのみとし、支払方法、購入グループ、都道府県、性別、利用端末、年代(会員)は削除する
B94: スマレジについて
C95: ・ | D95: スマレジの取引データは基本的にリアルタイムに送信される
C96: ・ | D96: 本店のほか、支店やスマレジの取引情報も集計対象として取り扱う
B99: 識別ID | E99: ラベル | M99: 書式・制限 | T99: 必須 | V99: 最大値 | Z99: 初期値 | AG99: 画面部品の説明
B100: 1 | E100: キーワード検索 | M100: テキストボックス | T100: - | Z100: - | AG100: 検索対象 : 商品名(日/英)・カード名・商品コード・備考
B101: 2 | E101: 検索枠表示・非表示ボタン | M101: ボタン | T101: - | Z101: - | AG101: 検索枠(識別ID 2～15)の表示・非表示
B102: 3 | E102: 集計対象(通販) | M102: チェックボックス | T102: - | Z102: - | AG102: 検索結果に「通販売上集計」を含める場合はチェックを入れる
B103: 4 | E103: 集計対象(各店舗) | M103: チェックボックス (店舗毎) | T103: - | Z103: - | AG103: 店舗一覧から「店舗売上集計」をしたい店舗にチェックを入れる。ログインユーザーの所属店舗には自動的にチェックが入る。
B104: 5 | E104: 店舗全選択/全解除 | M104: チェックボックス | T104: - | Z104: - | AG104: チェックボックスの設定に沿って、すべての各店舗のチェックボックスと連動
B105: 6 | E105: 集計日(From) | M105: 日時(yyyy/mm/dd hh:mm:ss) | T105: - | Z105: 当月1日 | AG105: 集計開始日時を指定する
...

Sheet 受注売上分析 集計一覧(検索結果-集計単位 商品)
A1: ドキュメント名 | I1: =表紙!$B$7 -> 分析・集計管理機能 | U1: セクション
A2: プロジェクト名 | I2: =表紙!$B$5 -> サイトリニューアル | U2: 作成者 | Y2: 高久 | AC2: 作成日 | AG2: 45847 | AK2: 更新者 | AS2: 更新日
A4: 機能No | D4: M12-03 | I4: 機能名 | N4: 受注売上分析 集計一覧(検索結果) 集計単位:商品 | AC4: 概要 | AG4: 受注データを使って集計単位を指定して集計を行うことが可能
B6: レイアウト図
B42: カスタマイズ説明
B43: ・カスタマイズ要件
C44: ・ | D44: 出力結果項目について
C45: ・ | D45: スマレジについて
C47: カスタマイズ要件に記載の内容以外は現行踏襲とする
B50: 処理概要（★はカスタマイズ項目）
B51: 概要
C52: 受注データを使って集計単位を指定して集計を行うことが可能
C53: (集計日期間内の集計日対象項目の商品ごとの統計を行う)
B55: 機能
C56: 現行機能をベースに下記のカスタマイズを行う
B58: 出力結果項目について
C59: ・ | D59: 下記の項目を削除
D60: ・ | E60: 数量割合
D61: ・ | E61: 合計割合
D62: ・ | E62: 件数割合
B64: スマレジについて
C65: ・ | D65: スマレジの取引データは基本的にリアルタイムに送信される
C66: ・ | D66: 本店のほか、支店やスマレジの取引情報も集計対象として取り扱う
B69: 識別ID | E69: ラベル | M69: 書式・制限 | T69: 必須 | V69: 最大値 | Z69: 初期値 | AG69: 画面部品の説明
B70: 1 | E70: 商品コード | M70: ラベル | T70: - | V70: - | Z70: -
B71: 2 | E71: 商品名 | M71: ラベル | T71: - | V71: - | Z71: -
B72: 3 | E72: 平均単価 | M72: ラベル | T72: - | V72: - | Z72: -
B73: 4 | E73: 数量 | M73: ラベル | T73: - | V73: - | Z73: -
B74: 5 | E74: 合計 | M74: ラベル | T74: - | V74: - | Z74: -
B75: 6 | E75: 件数 | M75: ラベル | T75: - | V75: - | Z75: -
B76: 7 | E76: 数量累計 | M76: ラベル | T76: - | V76: - | Z76: - | AG76: 識別ID 4 :「数量」の総合計
B77: 8 | E77: 合計累計 | M77: ラベル | T77: - | V77: - | Z77: - | AG77: 識別ID 5 :「合計」の総合計
B78: 9 | E78: 件数累計 | M78: ラベル | T78: - | V78: - | Z78: - | AG78: 識別ID 6 :「件数」の総合計
B79: 10 | E79: CSVダウンロード | M79: リンク | T79: - | V79: - | Z79: -

Sheet 受注売上分析 集計一覧(検索結果-集計単位 カテゴリ )
A1: ドキュメント名 | I1: =表紙!$B$7 -> 分析・集計管理機能 | U1: セクション
A2: プロジェクト名 | I2: =表紙!$B$5 -> サイトリニューアル | U2: 作成者 | Y2: 高久 | AC2: 作成日 | AG2: 45847 | AK2: 更新者 | AS2: 更新日
A4: 機能No | D4: M12-03 | I4: 機能名 | N4: 受注売上分析 集計一覧(検索結果) 集計単位:カテゴリ | AC4: 概要 | AG4: 受注データを使って集計単位を指定して集計を行うことが可能
B6: レイアウト図
B42: カスタマイズ説明
B43: ・カスタマイズ要件
C44: ・ | D44: 出力結果項目について
C45: ・ | D45: スマレジについて
C47: カスタマイズ要件に記載の内容以外は現行踏襲とする
B50: 処理概要（★はカスタマイズ項目）
B51: 概要
C52: 受注データを使って集計単位を指定して集計を行うことが可能
C53: (集計日期間内の集計日対象項目のカテゴリごとの統計を行う)
B55: 機能
C56: 現行機能をベースに下記のカスタマイズを行う
B58: 出力結果項目について
C59: ・ | D59: 下記の項目を削除
D60: ・ | E60: 数量割合
D61: ・ | E61: 合計割合
D62: ・ | E62: 件数割合
B64: スマレジについて
C65: ・ | D65: スマレジの取引データは基本的にリアルタイムに送信される
C66: ・ | D66: 本店のほか、支店やスマレジの取引情報も集計対象として取り扱う
B69: 識別ID | E69: ラベル | M69: 書式・制限 | T69: 必須 | V69: 最大値 | Z69: 初期値 | AG69: 画面部品の説明
B70: 1 | E70: カテゴリ | M70: ラベル | T70: - | V70: - | Z70: -
B71: 2 | E71: 平均単価 | M71: ラベル | T71: - | V71: - | Z71: -
B72: 3 | E72: 数量 | M72: ラベル | T72: - | V72: - | Z72: -
B73: 4 | E73: 合計 | M73: ラベル | T73: - | V73: - | Z73: -
B74: 5 | E74: 件数 | M74: ラベル | T74: - | V74: - | Z74: -
B75: 6 | E75: 数量累計 | M75: ラベル | T75: - | V75: - | Z75: - | AG75: 識別ID 3 :「数量」の総合計
B76: 7 | E76: 合計累計 | M76: ラベル | T76: - | V76: - | Z76: - | AG76: 識別ID 4 :「合計」の総合計
B77: 8 | E77: 件数累計 | M77: ラベル | T77: - | V77: - | Z77: - | AG77: 識別ID 5 :「件数」の総合計
B78: 9 | E78: CSVダウンロード | M78: リンク | T78: - | V78: - | Z78: -

Sheet 受注売上分析 CSV出力(商品)
A1: ドキュメント名 | I1: =表紙!$B$7 -> 分析・集計管理機能 | U1: セクション
A2: プロジェクト名 | I2: =表紙!$B$5 -> サイトリニューアル | U2: 作成者 | Y2: 高久 | AC2: 作成日 | AG2: 45847 | AK2: 更新者 | AS2: 更新日
A4: 機能No | D4: M12-04 | I4: 機能名 | N4: 受注/売上分析 CSV出力(商品) | AC4: 概要 | AG4: 受注データを使って集計単位を指定して集計を行うことが可能
B6: M12-04 受注/売上分析 CSV出力(商品)
B7: 識別ID | E7: 項目名 | M7: 備考
B8: 1 | E8: 商品コード
B9: 2 | E9: 商品名
B10: 3 | E10: 平均単価
B11: 4 | E11: 数量
B12: 5 | E12: 合計
B13: 6 | E13: 件数
B15: カスタマイズ説明
B16: ・カスタマイズ要件
C17: ・ | D17: 出力結果項目について
C18: ・ | D18: スマレジについて
C20: カスタマイズ要件に記載の内容以外は現行踏襲とする
B22: 処理概要（★はカスタマイズ項目）
B23: 概要
C24: 受注データを使って集計単位を指定して集計を行うことが可能
B26: 機能
C27: 現行機能をベースに下記のカスタマイズを行う
B29: 出力結果項目について
C30: ・ | D30: 下記の項目を削除
D31: ・ | E31: 数量割合
D32: ・ | E32: 合計割合
D33: ・ | E33: 件数割合
B35: スマレジについて
C36: ・ | D36: スマレジの取引データは基本的にリアルタイムに送信される
C37: ・ | D37: 本店のほか、支店やスマレジの取引情報も集計対象として取り扱う

Sheet 受注売上分析 CSV出力(カテゴリ)
A1: ドキュメント名 | I1: =表紙!$B$7 -> 分析・集計管理機能 | U1: セクション
A2: プロジェクト名 | I2: =表紙!$B$5 -> サイトリニューアル | U2: 作成者 | Y2: 高久 | AC2: 作成日 | AG2: 45847 | AK2: 更新者 | AS2: 更新日
A4: 機能No | D4: M12-04 | I4: 機能名 | N4: 受注/売上分析 CSV出力(カテゴリ) | AC4: 概要 | AG4: 受注データを使って集計単位を指定して集計を行うことが可能
B6: M12-04 受注/売上分析 CSV出力(商品以外)
B7: 識別ID | E7: 項目名 | M7: 備考
B8: 1 | E8: カテゴリ
B9: 2 | E9: 平均単価
B10: 3 | E10: 数量
B11: 4 | E11: 合計
B12: 5 | E12: 件数
B14: カスタマイズ説明
B15: ・カスタマイズ要件
C16: ・ | D16: 出力結果項目について
C17: ・ | D17: スマレジについて
C19: カスタマイズ要件に記載の内容以外は現行踏襲とする
B22: 処理概要（★はカスタマイズ項目）
B23: 概要
C24: 受注データを使って集計単位を指定して集計を行うことが可能
C25: (集計一覧表示(検索項目) 識別ID 5:「集計単位」で指定した項目ごとの統計を行う)
B27: 機能
C28: 現行機能をベースに下記のカスタマイズを行う
B30: 出力結果項目について
C31: ・ | D31: 下記の項目を削除
D32: ・ | E32: 数量割合
D33: ・ | E33: 合計割合
D34: ・ | E34: 件数割合
B36: スマレジについて
C37: ・ | D37: スマレジの取引データは基本的にリアルタイムに送信される
C38: ・ | D38: 本店のほか、支店やスマレジの取引情報も集計対象として取り扱う

Sheet 入荷通知依頼 一覧表示(検索項目)
A1: ドキュメント名 | I1: =表紙!$B$7 -> 分析・集計管理機能 | U1: セクション
A2: プロジェクト名 | I2: =表紙!$B$5 -> サイトリニューアル | U2: 作成者 | Y2: 高久 | AC2: 作成日 | AG2: 45847 | AK2: 更新者 | AO2: 堀部 | AS2: 更新日 | AW2: 45957
A4: 機能No | D4: M12-05 | I4: 機能名 | N4: 入荷通知依頼 | AC4: 概要 | AG4: フロントにて入荷通知を受け取る依頼がされた商品を確認することができる
B6: レイアウト図
B33: カスタマイズ説明
B34: ・カスタマイズ要件
C35: ・ | D35: 入荷通知範囲の変更
C36: ・ | D36: 言語指定項目の追加
C37: ・ | D37: キーワード検索から「会員名」での検索を削除
C38: カスタマイズ要件に記載の内容以外は現行踏襲とする
B41: 処理概要（★はカスタマイズ項目）
B42: 概要
C43: フロントにて入荷通知を受け取る依頼がされた商品を確認することができる
B45: 機能
C46: 現行機能をベースに下記のカスタマイズを行う
B48: 入荷通知範囲の変更
C49: ・ | D49: 商品単位でも入荷通知依頼を設定できるようになるため、商品単位の入荷通知依頼を出力可能とする
B51: 言語指定項目の追加
C52: ・ | D52: 言語の指定できるようになるため、言語指定による入荷通知依頼の出力が可能
B54: キーワード検索から会員名を削除
C55: ・ | D55: 商品ごとの集計結果を表示するため、会員名での検索を削除
B58: 識別ID | E58: ラベル | M58: 書式・制限 | T58: 必須 | V58: 最大値 | Z58: 初期値 | AG58: 画面部品の説明
B59: 1 | E59: キーワード検索 | M59: テキストボックス | T59: - | Z59: - | AG59: 検索対象 : 商品名(日/英)
B60: =B59+1 -> 2 | E60: 検索枠表示・非表示ボタン | M60: ボタン | T60: - | Z60: - | AG60: 検索枠(識別ID 3～13)の表示・非表示
B61: =B60+1 -> 3 | E61: 依頼日(From) | M61: 日付(yyyy/mm/dd) | T61: - | Z61: 当月1日 | AG61: 依頼日範囲指定の開始日を指定する
B62: =B61+1 -> 4 | E62: 依頼日(To) | M62: 日付(yyyy/mm/dd) | T62: - | Z62: 当月末日 | AG62: 依頼日範囲指定の終了日を指定する
B63: =B62+1 -> 5 | E63: 販売金額(From) | M63: 数値 | T63: - | Z63: - | AG63: 販売金額の範囲(最大値)を指定
B64: =B63+1 -> 6 | E64: 販売金額(To) | M64: 数値 | T64: - | Z64: - | AG64: 販売金額の範囲(最小値)を指定
B65: =B64+1 -> 7 | E65: 言語 | M65: チェックボックス | AG65: 日本語・英語・その他言語の言語指定
B66: =B65+1 -> 8 | E66: 並び替え(項目) | M66: リストボックス | T66: - | Z66: - | AG66: 並べ替えする項目を指定
B67: =B66+1 -> 9 | E67: 並び替え(並び順) | M67: ラジオボックス | T67: - | Z67: - | AG67: 上記の並び替え(項目)の並び順を指定 選択肢:昇順・降順
B68: =B67+1 -> 10 | E68: 売上分析タグ | M68: 複数テキストボックス | T68: - | Z68: - | AG68: 商品管理 - 売上分析タグで登録されているデータから選択
B69: =B68+1 -> 11 | E69: 表示件数 | M69: チェックボックス | T69: - | Z69: - | AG69: 検索結果に表示する件数の上限を指定。選択肢は、 ページング機能で共通利用されるマスターデータ（mtb_page_max）の値
B70: =B69+1 -> 12 | E70: 検索条件をクリア | M70: リンク | T70: - | Z70: - | AG70: 識別ID 1～12(2を除く) の入力内容をすべて初期値に戻す
B71: =B70+1 -> 13 | E71: 検索ボタン | M71: ボタン | T71: - | Z71: -

Sheet 入荷通知依頼 一覧表示(検索結果)
A1: ドキュメント名 | I1: =表紙!$B$7 -> 分析・集計管理機能 | U1: セクション
A2: プロジェクト名 | I2: =表紙!$B$5 -> サイトリニューアル | U2: 作成者 | Y2: 高久 | AC2: 作成日 | AG2: 45847 | AK2: 更新者 | AO2: 堀部 | AS2: 更新日 | AW2: 45952
A4: 機能No | D4: M12-05 | I4: 機能名 | N4: 入荷通知依頼 | AC4: 概要 | AG4: フロントにて入荷通知を受け取る依頼がされた商品を確認することができる
B6: レイアウト図
B27: カスタマイズ説明
B28: ・カスタマイズ要件
C29: ・ | D29: 商品IDの追加
C30: ・ | D30: 言語の追加
C31: ・ | D31: 各カウント数について
C33: カスタマイズ要件に記載の内容以外は現行踏襲とする
B36: 処理概要（★はカスタマイズ項目）
B37: 概要
C38: フロントにて入荷通知を受け取る依頼がされた商品を確認することができる
B40: 機能
C41: 現行機能をベースに下記のカスタマイズを行う
B43: 商品IDの追加
C44: ・ | D44: 識別ID 1:商品IDの追加
C45: ・ | D45: 識別ID 2:言語の追加
B47: 各カウント数について
C48: ・ | D48: 識別ID 4:「通知待ち」の追加
D49: 検索項目で指定した条件に該当する商品ごとの入荷通知待ち件数を取得
D50: 商品規格ごとに設定されている場合、異なる規格であっても同じ商品で登録している場合は1カウントとし、規格ごとにカウントしない。
C51: ・ | D51: 識別ID 5:「削除」の追加
D52: 検索項目で指定した条件に該当する商品ごとのユーザー自身が通知取り消しを行った件数を取得
D53: 商品規格ごとに設定されている場合、すべての規格および商品IDが削除されている場合のみ削除にカウントする。
B56: 識別ID | E56: ラベル | M56: 書式・制限 | T56: 必須 | V56: 最大値 | Z56: 初期値 | AG56: 画面部品の説明
B57: 1 | E57: 商品ID | M57: ラベル | T57: - | V57: - | Z57: - | AG57: 入荷通知依頼を行った商品ID
C58: 2 | E58: 言語 | M58: ラベル | T58: - | V58: - | Z58: -
B59: 3 | E59: 商品名 | M59: ラベル | T59: - | V59: - | Z59: -
B60: 4 | E60: 通知待ち | M60: ラベル | T60: - | V60: - | Z60: -
B61: 5 | E61: 削除 | M61: ラベル | T61: - | V61: - | Z61: -
B62: 6 | E62: 入荷通知一覧CSV出力 | M62: リンク | T62: - | V62: - | Z62: -

Sheet 入荷通知依頼 CSV出力
A1: ドキュメント名 | I1: =表紙!$B$7 -> 分析・集計管理機能 | U1: セクション
A2: プロジェクト名 | I2: =表紙!$B$5 -> サイトリニューアル | U2: 作成者 | Y2: 高久 | AC2: 作成日 | AG2: 45847 | AK2: 更新者 | AS2: 更新日
A4: 機能No | D4: M12-06 | I4: 機能名 | N4: 入荷通知依頼 CSV出力 | AC4: 概要 | AG4: フロントにて入荷通知を受け取る依頼がされた商品をCSVダウンロードすることができる
B6: M12-06 入荷通知依頼 CSV出力
B7: 識別ID | E7: 項目名 | M7: 備考
B8: 1 | E8: 商品ID | M8: ※カスタマイズ対応
C9: 2 | E9: 言語ID | M9: ※カスタマイズ対応
B10: 3 | E10: 商品名
B11: 4 | E11: 通知待ち | M11: ※カスタマイズ対応
B12: 5 | E12: 削除 | M12: ※カスタマイズ対応
B14: カスタマイズ説明
B15: ・カスタマイズ要件
C16: ・ | D16: 商品IDの追加
C17: ・ | D17: 言語IDの追加
C18: ・ | D18: 各カウント数について
C20: カスタマイズ要件に記載の内容以外は現行踏襲とする
B23: 処理概要（★はカスタマイズ項目）
B24: 概要
C25: フロントにて入荷通知を受け取る依頼がされた商品を確認することができる
B27: 機能
C28: 現行機能をベースに下記のカスタマイズを行う
B30: 商品IDの追加
C31: ・ | D31: 識別ID 1:商品IDの追加
C32: ・ | D32: 識別ID 2:言語IDの追加
B34: 言語指定項目の追加
C35: ・ | D35: 識別ID 4:「通知待ち」の追加
D36: 検索項目で指定した条件に該当する商品ごとの入荷通知待ち件数を取得
D37: 商品規格ごとに設定されている場合、異なる規格であっても同じ商品で登録している場合は1カウントとし、規格ごとにカウントしない。
C38: ・ | D38: 識別ID 5:「削除」の追加
D39: 検索項目で指定した条件に該当する商品ごとのユーザー自身が通知取り消しを行った件数を取得
D40: 商品規格ごとに設定されている場合、異なる規格であっても同じ商品で登録している場合は1カウントとし、規格ごとにカウントしない。

Sheet フォーマット売上分析 集計一覧(検索項目)
A1: ドキュメント名 | I1: =表紙!$B$7 -> 分析・集計管理機能 | U1: セクション
A2: プロジェクト名 | I2: =表紙!$B$5 -> サイトリニューアル | U2: 作成者 | Y2: 高久 | AC2: 作成日 | AG2: 45847 | AK2: 更新者 | AS2: 更新日
A4: 機能No | D4: M12-07 | I4: 機能名 | N4: フォーマット売上分析 集計一覧表示 | AC4: 概要 | AG4: 受注データを使って受注データに紐づく売上分析タグ別に集計を行うことが可能
B6: レイアウト図
B42: カスタマイズ説明
B43: ・カスタマイズ要件
C44: ・ | D44: 売上分析の集計対象を指定
C45: ・ | D45: スマレジについて
C47: カスタマイズ要件に記載の内容以外は現行踏襲とする
B49: 処理概要（★はカスタマイズ項目）
B50: 概要
C51: 受注データを使って受注データに紐づく売上分析タグ別に集計を行うことが可能
B53: 機能
C54: 現行機能をベースに下記のカスタマイズを行う
B56: 売上分析の集計対象を指定
C57: 識別ID 2:集計対象(通販)を追加。「通販」を集計対象として含める場合、チェックを入れる
C58: 識別ID 3:集計対象(店舗)を追加。「全店舗」を集計対象として含める場合、チェックを入れる
C59: 上記両方チェックを入れた場合は、「通販」「全店舗」両方集計対象とする。
B61: スマレジについて
C62: ・ | D62: スマレジの取引データは基本的にリアルタイムに送信される
C63: ・ | D63: 本店のほか、支店やスマレジの取引情報も集計対象として取り扱う
B66: 識別ID | E66: ラベル | M66: 書式・制限 | T66: 必須 | V66: 最大値 | Z66: 初期値 | AG66: 画面部品の説明
B67: 1 | E67: 集計月 | M67: 年月(yyyy-mm) | T67: 〇 | V67: - | Z67: -
C68: 2 | E68: 集計対象(通販) | M68: チェックボックス | T68: ※ | Z68: チェックON | AG68: 集計対象に「通販」を含める
C69: 3 | E69: 集計対象(店舗) | M69: チェックボックス | T69: ※ | Z69: チェックON | AG69: 集計対象に「全店舗」を含める
B70: 4 | E70: 検索ボタン | M70: ボタン | T70: - | V70: - | Z70: -
B71: ※識別ID2:集計対象(通販)・識別ID3 :集計対象(店舗)は必ず1つ以上はチェックを入れる必要があります

Sheet フォーマット売上分析 集計一覧(検索結果) 
A1: ドキュメント名 | I1: =表紙!$B$7 -> 分析・集計管理機能 | U1: セクション
A2: プロジェクト名 | I2: =表紙!$B$5 -> サイトリニューアル | U2: 作成者 | Y2: 高久 | AC2: 作成日 | AG2: 45847 | AK2: 更新者 | AS2: 更新日
A4: 機能No | D4: M12-07 | I4: 機能名 | N4: フォーマット売上分析 集計一覧表示 | AC4: 概要 | AG4: 受注データを使って受注データに紐づく売上分析タグ別に集計を行うことが可能
B6: レイアウト図
B42: カスタマイズ説明
B43: ・カスタマイズ要件
C44: ・ | D44: スマレジについて
C46: カスタマイズ要件に記載の内容以外は現行踏襲とする
B48: 処理概要（★はカスタマイズ項目）
B49: 概要
C50: 受注データを使って受注データに紐づく売上分析タグ別に集計を行うことが可能
B52: 機能
C53: 現行機能をベースに下記のカスタマイズを行う
B55: スマレジについて
C56: ・ | D56: スマレジの取引データは基本的にリアルタイムに送信される
C57: ・ | D57: 本店のほか、支店やスマレジの取引情報も集計対象として取り扱う
B60: 識別ID | E60: ラベル | M60: 書式・制限 | T60: 必須 | V60: 最大値 | Z60: 初期値 | AG60: 画面部品の説明
B61: 1 | E61: 日毎売上分析タグ毎売上 (グラフ) | M61: - | T61: - | V61: - | Z61: -
B62: 2 | E62: 日毎売上分析タグ毎売上 (一覧) | M62: - | T62: - | V62: - | Z62: -
B63: 3 | E63: 売上分析タグ毎売上合計 | M63: - | T63: - | V63: - | Z63: -
B64: 4 | E64: 売上分析タグ毎売上平均 | M64: - | T64: - | V64: - | Z64: -
B65: 5 | E65: CSVダウンロード | M65: ボタン | T65: - | V65: - | Z65: -

Sheet フォーマット売上分析 CSV出力
A1: ドキュメント名 | I1: =表紙!$B$7 -> 分析・集計管理機能 | U1: セクション
A2: プロジェクト名 | I2: =表紙!$B$5 -> サイトリニューアル | U2: 作成者 | Y2: 高久 | AC2: 作成日 | AG2: 45847 | AK2: 更新者 | AS2: 更新日
A4: 機能No | D4: M12-08 | I4: 機能名 | N4: フォーマット売上分析 CSV出力 | AC4: 概要 | AG4: 受注データを使って受注データに紐づく売上分析タグ別に集計を行うことが可能
B6: M12-08 フォーマット売上分析 CSVダウンロード
B7: 識別ID | E7: 項目名 | M7: 備考
B8: 1 | E8: 日
B9: 2 | E9: スタンダード
B10: 3 | E10: パイオニア(RTR～)
B11: 4 | E11: モダン(MRD～M13)
B12: 5 | E12: レガシー
B13: 6 | E13: ヴィンテージ
B14: 7 | E14: スタンFoil
B15: 8 | E15: 絶版Foil(スタン除く)
B16: 9 | E16: サプライ
B17: 10
B18: 11
B19: 12
B20: 13
B21: 14
B22: 15
B23: α-2 | E23: その他(カード)
B24: α-1 | E24: その他
B25: α | E25: 合計
B27: カスタマイズ説明
B28: ・カスタマイズ要件
C29: ・ | D29: スマレジについて
C31: カスタマイズ要件に記載の内容以外は現行踏襲とする
B33: 処理概要（★はカスタマイズ項目）
B34: 概要
C35: 受注データを使って受注データに紐づく売上分析タグ別に集計を行うことが可能
B37: 機能
C38: 現行機能をベースに下記のカスタマイズを行う
B40: スマレジについて
C41: ・ | D41: スマレジの取引データは基本的にリアルタイムに送信される
C42: ・ | D42: 本店のほか、支店やスマレジの取引情報も集計対象として取り扱う

Sheet 特集タグ編集CSVダウンロード(検索項目)
A1: ドキュメント名 | I1: =表紙!$B$7 -> 分析・集計管理機能 | U1: セクション
A2: プロジェクト名 | I2: =表紙!$B$5 -> サイトリニューアル | U2: 作成者 | Y2: 高久 | AC2: 作成日 | AG2: 45847 | AK2: 更新者 | AS2: 更新日
A4: 機能No | D4: M12-09 | I4: 機能名 | N4: 特集タグ編集CSVダウンロード | AC4: 概要 | AG4: 特集タグ編集CSVをダウンロードすることができる
B6: レイアウト図
B23: カスタマイズ説明
B24: ・カスタマイズ要件
C25: ・ | D25: 採用枚数略式CSVダウンロードの廃止
C27: カスタマイズ要件に記載の内容以外は現行踏襲とする
B29: 処理概要（★はカスタマイズ項目）
B30: 概要
C31: 特集タグ編集CSVをダウンロードすることができる
B33: 機能
C34: 現行機能をベースに下記のカスタマイズを行う
B36: 採用枚数略式CSVダウンロードの廃止
C37: ・ | D37: 採用枚数略式CSVダウンロードは利用頻度が少ないため、今回のカスタマイズで廃止する
C38: ・ | D38: 特集タグ編集用CSVダウンロードは現行踏襲
B41: 識別ID | E41: ラベル | M41: 書式・制限 | T41: 必須 | V41: 最大値 | Z41: 初期値 | AG41: 画面部品の説明
B42: 1 | E42: 集計日(From) | M42: 日付(yyyy/mm/dd) | T42: 〇 | V42: - | Z42: 2週間前の日付 | AG42: 集計開始日付を指定する
B43: 2 | E43: 集計日(To) | M43: 日付(yyyy/mm/dd) | T43: - | V43: - | Z43: - | AG43: 集計終了日付を指定する
C44: 3 | E44: フォーマット | M44: リスト | T44: 〇 | V44: - | Z44: - | AG44: 商品カードのフォーマットから選択
C45: 4 | E45: 基本土地項目追加 | M45: チェックボックス | T45: - | V45: - | Z45: -
B46: 5 | E46: 特集タグ編集CSVダウンロード | M46: ボタン | T46: - | V46: - | Z46: -
B47: 6 | E47: 検索条件をクリア | M47: リンク | T47: - | V47: - | Z47: - | AG47: 検索条件入力項目を初期状態に戻す

Sheet 特集タグ編集CSVダウンロード CSV出力
A1: ドキュメント名 | I1: =表紙!$B$7 -> 分析・集計管理機能 | U1: セクション
A2: プロジェクト名 | I2: =表紙!$B$5 -> サイトリニューアル | U2: 作成者 | Y2: 高久 | AC2: 作成日 | AG2: 45847 | AK2: 更新者 | AS2: 更新日
A4: 機能No | D4: M12-10 | I4: 機能名 | N4: 特集タグ編集CSVダウンロード | AC4: 概要 | AG4: 特集タグ編集CSVをダウンロードすることができる
B6: M12-10 特集タグ編集 CSVダウンロード
B7: 識別ID | E7: 項目名 | M7: 備考
B8: 1 | E8: 商品ID
B9: 2 | E9: 商品コード
B10: 3 | E10: 商品名(日)
B11: 4 | E11: 在庫数 | M11: 本店ECの在庫数
B12: 5 | E12: 販売価格
B13: 6 | E13: 買取価格
B14: 7 | E14: 言語(ID)
B15: 8 | E15: カード名(英)
B16: 9 | E16: カードセット略称
B17: 10 | E17: レアリティ
B18: 11 | E18: Foilフラグ
B19: 12 | E19: 状態コード
B20: 13 | E20: 当日販売数 | M20: 本店ECの販売数
B21: 14 | E21: 1週間販売数 | M21: 本店ECの販売数
B22: 15 | E22: 1ヵ月間販売数 | M22: 本店ECの販売数
B23: 16 | E23: 採用枚数
B24: 17 | E24: タグ
B26: カスタマイズ説明
C28: カスタマイズ要件がなく、現行踏襲とする
B31: 処理概要（★はカスタマイズ項目）
B32: 概要
C33: 特集タグ編集CSVをダウンロードすることができる
B35: 機能
C36: 現行機能から変更なし

Sheet XXXCSV出力項目設定
A1: ドキュメント名 | U1: セクション
A2: プロジェクト名 | U2: 作成者 | AC2: 作成日 | AK2: 更新者 | AS2: 更新日
B4: XXXCSV出力項目設定
B5: 識別ID | E5: 項目名 | M5: 備考
B6: 1 | E6: 項目名A
B7: 2 | E7: 項目名B
B8: 3 | E8: 項目名C
B9: 4 | E9: 項目名D
B10: 5 | E10: 項目名E
B11: 6 | E11: 項目名F
B12: 7 | E12: 項目名G
B13: 8 | E13: 項目名H
B14: 9 | E14: 項目名I
B15: 10 | E15: 項目名J
B16: 11 | E16: 項目名K
B17: 12 | E17: 項目名L
... B31: 26 | E31: 項目名Z

Sheet 対応状況管理
A1: ドキュメント名 | U1: セクション
A2: プロジェクト名 | U2: 作成者 | AC2: 作成日 | AK2: 更新者 | AS2: 更新日
B4: 対応状況一覧
B5: 識別ID | E5: 表示名（管理画面） | M5: 表示名（フロント画面） | V5: 備考
B6: 1 | E6: 新規受付 | M6: ご予約中 | V6: 予約フォームからの送信、管理画面からの予約新規登録時の対応状況
B7: 2 | E7: ご案内中 | M7: 入荷ご案内中 | V7: 予約商品の在庫が確保でき、販売のご案内メールを送信したタイミングで自動でこの対応状況に変更される
B8: 3 | E8: 確認処理中 | M8: ご予約内容確認中 | V8: 予約者について確認事項がある際などに、管理運用で使用する対応状況（管理画面での対応状況変更操作）
B9: 4 | E9: 受注済み | M9: ご注文済み | V9: 予約販売商品が購入されたタイミングで自動でこの対応状況に変更される
B10: 5 | E10: リマインド済み | M10: 入荷ご案内中 | V10: リマインドメールを送信したタイミングで自動でこの対応状況に変更される
B11: 6 | E11: キャンセル | M11: キャンセル | V11: 予約がキャンセルになった場合の対応状況（管理画面での対応状況変更操作）
B13: 対応状況の流れ

Sheet メール管理_商品予約完了
A1: ドキュメント名 | U1: セクション
A2: プロジェクト名 | U2: 作成者 | AC2: 作成日 | AK2: 更新者 | AS2: 更新日
B4: メール情報
B5: カテゴリ名 | I5: テンプレート名 | R5: To | Y5: Cc、Bcc | AG5: 送信タイミング | AO5: 内容、目的
B6: 予約完了 | I6: 商品予約完了 | R6: 予約フォームに入力された予約者のメールアドレス | Y6: Bcc： xxxxxxxxxxxxxx@xxxxxxxx※内部処理は注文メールと合わせる想定 | AG6: フロント画面 ・予約フォーム内容送信時 [自動送信] 管理画面 ・予約編集 [手動送信] | AO6: フロント予約フォームから内容送信時に自動で送信される。管理画面から作成した予約については、予約編集画面からメールを送信できる。
B8: メールタイトル
B9: 【▲▲▲▲】商品予約完了のお知らせ
B11: メール本文
C74: ※メール本文の動的部分は {コード名} の形式で記載。コードと内容の対応は以下を参照。
C76: コード対応表
C77: コード名 | L77: 内容
C78: name01 | L78: 予約時に入力された名前（姓）
C79: name02 | L79: 予約時に入力された名前（名）
C80: product_code | L80: 予約時の商品データの商品コード
C81: product_name | L81: 予約時の商品データの商品名
C82: email | L82: 予約時に入力されたメールアドレス
C83: phone_number | L83: 予約時に入力された電話番号
C84: postal_code | L84: 予約時に入力された郵便番号
C85: pref_name | L85: 予約時に選択された都道府県
C86: addr01 | L86: 予約時に入力された住所（市区町村）
C87: addr02 | L87: 予約時に入力された住所（番地・建物名）
C88: note | L88: 予約時に入力された備考
B92: メール本文例（コードに値が入っているイメージ）

Sheet 機能A
A1: ドキュメント名 | U1: セクション
A2: プロジェクト名 | U2: 作成者 | AC2: 作成日 | AK2: 更新者 | AS2: 更新日
A4: 機能No | D4: F06-10 | I4: 機能名 | N4: 機能名 | AC4: 概要 | AG4: 概要
B6: レイアウト図
B47: 説明
B48: ・xxxxxxxxxxxxxxxxxxxxx
B49: ・xxxxxxxxxxxxxxxxxxxxx
B50: ・xxxxxxxxxxxxxxxxxxxxx
B51: ・xxxxxxxxxxxxxxxxxxxxx
B54: 識別ID | E54: ラベル | M54: 画面部品の種類 | T54: 表示範囲 | AB54: 画面部品の説明
B55: 1 | E55: 項目A | M55: テキスト | T55: - | AB55: xxxxxxxxxxxxxxxx
B56: 2 | E56: 項目B | M56: テキスト | T56: - | AB56: xxxxxxxxxxxxxxxx
B57: 3 | E57: 項目C | M57: 画像 | T57: - | AB57: xxxxxxxxxxxxxxxx
B58: 4 | E58: 項目D | M58: テキスト | T58: - | AB58: xxxxxxxxxxxxxxxx
B59: 5 | E59: 項目E | M59: テキスト | T59: - | AB59: xxxxxxxxxxxxxxxx
B60: 6 | E60: 項目F | M60: テキスト | T60: - | AB60: xxxxxxxxxxxxxxxx
B61: 7 | E61: 項目G | M61: テキスト | T61: - | AB61: xxxxxxxxxxxxxxxx
B62: 8 | E62: 項目H | M62: ボタン | T62: - | AB62: xxxxxxxxxxxxxxxx
B63: 9 | E63: 項目I | M63: テキストリンク | T63: - | AB63: xxxxxxxxxxxxxxxx
B66: ○○がない場合のイメージ
B77: メッセージ
B78: ID | E78: 表示箇所/タイミング | T78: メッセージ内容
B79: 1 | E79: ○○がない場合の表示文言 | T79: ○○はありません。
